Workbook
Name Slicer_Age: #N/A
Name Slicer_CATEGORY: #N/A
Name Slicer_gender: #N/A
Name Slicer_loyalty_level: #N/A
Name Slicer_new_ds: #N/A
Name Slicer_Product_ID: #N/A
Name Slicer_Quantity: #N/A
Name Slicer_REGION1: #N/A
Name Slicer_Store_ID1: #N/A
Name Slicer_TOTAL_REVENUE: #N/A
Name Slicer_TOTAL_REVENUE1: #N/A
Name Slicer_Unit_Price: #N/A

Sheet Customer_Dim
A1: Customer_ID | B1: cust id | C1: Name | D1: name | E1: Age | F1: Gender | G1: gender | H1: City | I1: city | J1: State | K1: state | L1: Country | M1: country | N1: Loyalty_Level | O1: loyalty level
A2: CUST1000 | B2: =PROPER(TRIM(CLEAN(A2))) -> Cust1000 | C2: sheena bonilla | D2: =PROPER(TRIM(CLEAN(C2))) -> Sheena Bonilla | E2: 55 | F2: Male | G2: =PROPER(TRIM(CLEAN(F2))) -> Male | H2: Donaldton | I2: =PROPER(TRIM(CLEAN(H2))) -> Donaldton | J2: North Carolina | K2: =PROPER(TRIM(CLEAN(J2))) -> North Carolina | L2: USA | M2: =PROPER(TRIM(CLEAN(L2))) -> Usa | O2: =IF(ISBLANK(N2), "Unknown",N2) -> Unknown
A3: CUST1001 | B3: =PROPER(TRIM(CLEAN(A3))) -> Cust1001 | C3: Eugene Nelson | D3: =PROPER(TRIM(CLEAN(C3))) -> Eugene Nelson | E3: 26 | F3: Female | G3: =PROPER(TRIM(CLEAN(F3))) -> Female | H3: Phillipsmouth | I3: =PROPER(TRIM(CLEAN(H3))) -> Phillipsmouth | J3: North Dakota | K3: =PROPER(TRIM(CLEAN(J3))) -> North Dakota | L3: USA | M3: =PROPER(TRIM(CLEAN(L3))) -> Usa | N3: Platinum | O3: =IF(ISBLANK(N3), "Unknown",N3) -> Platinum
A4: CUST1002 | B4: =PROPER(TRIM(CLEAN(A4))) -> Cust1002 | C4: dr. Benjamin Price | D4: =PROPER(TRIM(CLEAN(C4))) -> Dr. Benjamin Price | E4: 29 | F4: Female | G4: =PROPER(TRIM(CLEAN(F4))) -> Female | H4: Kylebury | I4: =PROPER(TRIM(CLEAN(H4))) -> Kylebury | J4: Alabama | K4: =PROPER(TRIM(CLEAN(J4))) -> Alabama | L4: USA | M4: =PROPER(TRIM(CLEAN(L4))) -> Usa | N4: Platinum | O4: =IF(ISBLANK(N4), "Unknown",N4) -> Platinum
A5: CUST1003 | B5: =PROPER(TRIM(CLEAN(A5))) -> Cust1003 | C5: jeremy harris | D5: =PROPER(TRIM(CLEAN(C5))) -> Jeremy Harris | E5: 59 | F5: Female | G5: =PROPER(TRIM(CLEAN(F5))) -> Female | H5: Thomastown | I5: =PROPER(TRIM(CLEAN(H5))) -> Thomastown | J5: Ohio | K5: =PROPER(TRIM(CLEAN(J5))) -> Ohio | L5: USA | M5: =PROPER(TRIM(CLEAN(L5))) -> Usa | N5: Bronze | O5: =IF(ISBLANK(N5), "Unknown",N5) -> Bronze
A6: CUST1004 | B6: =PROPER(TRIM(CLEAN(A6))) -> Cust1004 | C6: Caroline Collins | D6: =PROPER(TRIM(CLEAN(C6))) -> Caroline Collins | E6: 64 | F6: Female | G6: =PROPER(TRIM(CLEAN(F6))) -> Female | H6: Nicholasshire | I6: =PROPER(TRIM(CLEAN(H6))) -> Nicholasshire | J6: California | K6: =PROPER(TRIM(CLEAN(J6))) -> California | L6: USA | M6: =PROPER(TRIM(CLEAN(L6))) -> Usa | N6: Silver | O6: =IF(ISBLANK(N6), "Unknown",N6) -> Silver
A7: CUST1005 | B7: =PROPER(TRIM(CLEAN(A7))) -> Cust1005 | C7: Christine Vaughn | D7: =PROPER(TRIM(CLEAN(C7))) -> Christine Vaughn | E7: 24 | F7: Male | G7: =PROPER(TRIM(CLEAN(F7))) -> Male | H7: East Amandamouth | I7: =PROPER(TRIM(CLEAN(H7))) -> East Amandamouth | J7: Oregon | K7: =PROPER(TRIM(CLEAN(J7))) -> Oregon | L7: USA | M7: =PROPER(TRIM(CLEAN(L7))) -> Usa | N7: Bronze | O7: =IF(ISBLANK(N7), "Unknown",N7) -> Bronze
A8: CUST1006 | B8: =PROPER(TRIM(CLEAN(A8))) -> Cust1006 | C8: Amber Jackson | D8: =PROPER(TRIM(CLEAN(C8))) -> Amber Jackson | E8: 29 | F8: Female | G8: =PROPER(TRIM(CLEAN(F8))) -> Female | H8: Deborahborough | I8: =PROPER(TRIM(CLEAN(H8))) -> Deborahborough | J8: South Dakota | K8: =PROPER(TRIM(CLEAN(J8))) -> South Dakota | L8: USA | M8: =PROPER(TRIM(CLEAN(L8))) -> Usa | N8: Platinum | O8: =IF(ISBLANK(N8), "Unknown",N8) -> Platinum
A9: CUST1007 | B9: =PROPER(TRIM(CLEAN(A9))) -> Cust1007 | C9: Daniel Boyd | D9: =PROPER(TRIM(CLEAN(C9))) -> Daniel Boyd | E9: 29 | F9: Female | G9: =PROPER(TRIM(CLEAN(F9))) -> Female | H9: West Pamelafurt | I9: =PROPER(TRIM(CLEAN(H9))) -> West Pamelafurt | J9: West Virginia | K9: =PROPER(TRIM(CLEAN(J9))) -> West Virginia | L9: USA | M9: =PROPER(TRIM(CLEAN(L9))) -> Usa | N9: Bronze | O9: =IF(ISBLANK(N9), "Unknown",N9) -> Bronze
A10: CUST1008 | B10: =PROPER(TRIM(CLEAN(A10))) -> Cust1008 | C10: Melissa Howard | D10: =PROPER(TRIM(CLEAN(C10))) -> Melissa Howard | E10: 53 | F10: Female | G10: =PROPER(TRIM(CLEAN(F10))) -> Female | H10: Maynardton | I10: =PROPER(TRIM(CLEAN(H10))) -> Maynardton | J10: New Hampshire | K10: =PROPER(TRIM(CLEAN(J10))) -> New Hampshire | L10: USA | M10: =PROPER(TRIM(CLEAN(L10))) -> Usa | N10: Gold | O10: =IF(ISBLANK(N10), "Unknown",N10) -> Gold
A11: CUST1009 | B11: =PROPER(TRIM(CLEAN(A11))) -> Cust1009 | C11: Ms. Maria Leach | D11: =PROPER(TRIM(CLEAN(C11))) -> Ms. Maria Leach | E11: 64 | F11: Male | G11: =PROPER(TRIM(CLEAN(F11))) -> Male | H11: Melissashire | I11: =PROPER(TRIM(CLEAN(H11))) -> Melissashire | J11: Pennsylvania | K11: =PROPER(TRIM(CLEAN(J11))) -> Pennsylvania | L11: USA | M11: =PROPER(TRIM(CLEAN(L11))) -> Usa | N11: Platinum | O11: =IF(ISBLANK(N11), "Unknown",N11) -> Platinum
A12: CUST1010 | B12: =PROPER(TRIM(CLEAN(A12))) -> Cust1010 | C12: Dominic Page | D12: =PROPER(TRIM(CLEAN(C12))) -> Dominic Page | E12: 53 | F12: Male | G12: =PROPER(TRIM(CLEAN(F12))) -> Male | H12: Port Michaelburgh | I12: =PROPER(TRIM(CLEAN(H12))) -> Port Michaelburgh | J12: Pennsylvania | K12: =PROPER(TRIM(CLEAN(J12))) -> Pennsylvania | L12: USA | M12: =PROPER(TRIM(CLEAN(L12))) -> Usa | N12: Bronze | O12: =IF(ISBLANK(N12), "Unknown",N12) -> Bronze
A13: CUST1011 | B13: =PROPER(TRIM(CLEAN(A13))) -> Cust1011 | C13: Brian Lopez | D13: =PROPER(TRIM(CLEAN(C13))) -> Brian Lopez | E13: 28 | F13: Female | G13: =PROPER(TRIM(CLEAN(F13))) -> Female | H13: East Krista | I13: =PROPER(TRIM(CLEAN(H13))) -> East Krista | J13: New York | K13: =PROPER(TRIM(CLEAN(J13))) -> New York | L13: USA | M13: =PROPER(TRIM(CLEAN(L13))) -> Usa | N13: Gold | O13: =IF(ISBLANK(N13), "Unknown",N13) -> Gold
A14: CUST1012 | B14: =PROPER(TRIM(CLEAN(A14))) -> Cust1012 | C14: Kenneth Lambert | D14: =PROPER(TRIM(CLEAN(C14))) -> Kenneth Lambert | E14: 55 | F14: Female | G14: =PROPER(TRIM(CLEAN(F14))) -> Female | H14: North Kathryn | I14: =PROPER(TRIM(CLEAN(H14))) -> North Kathryn | J14: Kansas | K14: =PROPER(TRIM(CLEAN(J14))) -> Kansas | L14: USA | M14: =PROPER(TRIM(CLEAN(L14))) -> Usa | N14: Platinum | O14: =IF(ISBLANK(N14), "Unknown",N14) -> Platinum
... A19: CUST1017 | B19: =PROPER(TRIM(CLEAN(A19))) -> Cust1017 | C19: Adam Cruz | D19: =PROPER(TRIM(CLEAN(C19))) -> Adam Cruz | E19: 60 | F19: Female | G19: =PROPER(TRIM(CLEAN(F19))) -> Female | H19: Brandonville | I19: =PROPER(TRIM(CLEAN(H19))) -> Brandonville | J19: Georgia | K19: =PROPER(TRIM(CLEAN(J19))) -> Georgia | L19: USA | M19: =PROPER(TRIM(CLEAN(L19))) -> Usa | N19: Platinum | O19: =IF(ISBLANK(N19), "Unknown",N19) -> Platinum
A20: CUST1018 | B20: =PROPER(TRIM(CLEAN(A20))) -> Cust1018 | C20: Rhonda Moss | D20: =PROPER(TRIM(CLEAN(C20))) -> Rhonda Moss | E20: 43 | F20: Male | G20: =PROPER(TRIM(CLEAN(F20))) -> Male | H20: South William | I20: =PROPER(TRIM(CLEAN(H20))) -> South William | J20: Kansas | K20: =PROPER(TRIM(CLEAN(J20))) -> Kansas | L20: USA | M20: =PROPER(TRIM(CLEAN(L20))) -> Usa | O20: =IF(ISBLANK(N20), "Unknown",N20) -> Unknown
A21: CUST1019 | B21: =PROPER(TRIM(CLEAN(A21))) -> Cust1019 | C21: Michael Torres | D21: =PROPER(TRIM(CLEAN(C21))) -> Michael Torres | E21: 46 | F21: Female | G21: =PROPER(TRIM(CLEAN(F21))) -> Female | H21: Gonzalezfort | I21: =PROPER(TRIM(CLEAN(H21))) -> Gonzalezfort | J21: New Jersey | K21: =PROPER(TRIM(CLEAN(J21))) -> New Jersey | L21: USA | M21: =PROPER(TRIM(CLEAN(L21))) -> Usa | N21: Platinum | O21: =IF(ISBLANK(N21), "Unknown",N21) -> Platinum
A22: CUST1020 | B22: =PROPER(TRIM(CLEAN(A22))) -> Cust1020 | C22: Bridget Allen | D22: =PROPER(TRIM(CLEAN(C22))) -> Bridget Allen | E22: 59 | F22: Male | G22: =PROPER(TRIM(CLEAN(F22))) -> Male | H22: Lake Shaneburgh | I22: =PROPER(TRIM(CLEAN(H22))) -> Lake Shaneburgh | J22: Delaware | K22: =PROPER(TRIM(CLEAN(J22))) -> Delaware | L22: USA | M22: =PROPER(TRIM(CLEAN(L22))) -> Usa | N22: Silver | O22: =IF(ISBLANK(N22), "Unknown",N22) -> Silver
A23: CUST1021 | B23: =PROPER(TRIM(CLEAN(A23))) -> Cust1021 | C23: Jeff Martinez | D23: =PROPER(TRIM(CLEAN(C23))) -> Jeff Martinez | E23: 36 | F23: Female | G23: =PROPER(TRIM(CLEAN(F23))) -> Female | H23: Smithburgh | I23: =PROPER(TRIM(CLEAN(H23))) -> Smithburgh | J23: Oklahoma | K23: =PROPER(TRIM(CLEAN(J23))) -> Oklahoma | L23: USA | M23: =PROPER(TRIM(CLEAN(L23))) -> Usa | N23: Gold | O23: =IF(ISBLANK(N23), "Unknown",N23) -> Gold
A24: CUST1022 | B24: =PROPER(TRIM(CLEAN(A24))) -> Cust1022 | C24: paul fox | D24: =PROPER(TRIM(CLEAN(C24))) -> Paul Fox | E24: 33 | F24: Female | G24: =PROPER(TRIM(CLEAN(F24))) -> Female | H24: Michaelton | I24: =PROPER(TRIM(CLEAN(H24))) -> Michaelton | J24: Hawaii | K24: =PROPER(TRIM(CLEAN(J24))) -> Hawaii | L24: USA | M24: =PROPER(TRIM(CLEAN(L24))) -> Usa | N24: Silver | O24: =IF(ISBLANK(N24), "Unknown",N24) -> Silver
A25: CUST1023 | B25: =PROPER(TRIM(CLEAN(A25))) -> Cust1023 | C25: Jonathan Steele | D25: =PROPER(TRIM(CLEAN(C25))) -> Jonathan Steele | E25: 52 | F25: Female | G25: =PROPER(TRIM(CLEAN(F25))) -> Female | H25: Molinabury | I25: =PROPER(TRIM(CLEAN(H25))) -> Molinabury | J25: Oregon | K25: =PROPER(TRIM(CLEAN(J25))) -> Oregon | L25: USA | M25: =PROPER(TRIM(CLEAN(L25))) -> Usa | N25: Silver | O25: =IF(ISBLANK(N25), "Unknown",N25) -> Silver
A26: CUST1024 | B26: =PROPER(TRIM(CLEAN(A26))) -> Cust1024 | C26: Heather Collins | D26: =PROPER(TRIM(CLEAN(C26))) -> Heather Collins | E26: 40 | F26: Male | G26: =PROPER(TRIM(CLEAN(F26))) -> Male | H26: Rogerschester | I26: =PROPER(TRIM(CLEAN(H26))) -> Rogerschester | J26: Idaho | K26: =PROPER(TRIM(CLEAN(J26))) -> Idaho | L26: USA | M26: =PROPER(TRIM(CLEAN(L26))) -> Usa | N26: Platinum | O26: =IF(ISBLANK(N26), "Unknown",N26) -> Platinum
A27: CUST1025 | B27: =PROPER(TRIM(CLEAN(A27))) -> Cust1025 | C27: Diana Taylor | D27: =PROPER(TRIM(CLEAN(C27))) -> Diana Taylor | E27: 59 | F27: Female | G27: =PROPER(TRIM(CLEAN(F27))) -> Female | H27: Vasqueztown | I27: =PROPER(TRIM(CLEAN(H27))) -> Vasqueztown | J27: California | K27: =PROPER(TRIM(CLEAN(J27))) -> California | L27: USA | M27: =PROPER(TRIM(CLEAN(L27))) -> Usa | N27: Bronze | O27: =IF(ISBLANK(N27), "Unknown",N27) -> Bronze
A28: CUST1026 | B28: =PROPER(TRIM(CLEAN(A28))) -> Cust1026 | C28: Amber Carlson | D28: =PROPER(TRIM(CLEAN(C28))) -> Amber Carlson | E28: 18 | F28: Female | G28: =PROPER(TRIM(CLEAN(F28))) -> Female | H28: East Michellemouth | I28: =PROPER(TRIM(CLEAN(H28))) -> East Michellemouth | J28: Missouri | K28: =PROPER(TRIM(CLEAN(J28))) -> Missouri | L28: USA | M28: =PROPER(TRIM(CLEAN(L28))) -> Usa | N28: Gold | O28: =IF(ISBLANK(N28), "Unknown",N28) -> Gold
A29: CUST1027 | B29: =PROPER(TRIM(CLEAN(A29))) -> Cust1027 | C29: Leslie Johnson | D29: =PROPER(TRIM(CLEAN(C29))) -> Leslie Johnson | E29: 31 | F29: Male | G29: =PROPER(TRIM(CLEAN(F29))) -> Male | H29: Mollyshire | I29: =PROPER(TRIM(CLEAN(H29))) -> Mollyshire | J29: Utah | K29: =PROPER(TRIM(CLEAN(J29))) -> Utah | L29: USA | M29: =PROPER(TRIM(CLEAN(L29))) -> Usa | O29: =IF(ISBLANK(N29), "Unknown",N29) -> Unknown
A30: CUST1028 | B30: =PROPER(TRIM(CLEAN(A30))) -> Cust1028 | C30: Joshua Ryan | D30: =PROPER(TRIM(CLEAN(C30))) -> Joshua Ryan | E30: 27 | F30: Female | G30: =PROPER(TRIM(CLEAN(F30))) -> Female | H30: New David | I30: =PROPER(TRIM(CLEAN(H30))) -> New David | J30: New Jersey | K30: =PROPER(TRIM(CLEAN(J30))) -> New Jersey | L30: USA | M30: =PROPER(TRIM(CLEAN(L30))) -> Usa | N30: Platinum | O30: =IF(ISBLANK(N30), "Unknown",N30) -> Platinum
A31: CUST1029 | B31: =PROPER(TRIM(CLEAN(A31))) -> Cust1029 | C31: David Arnold | D31: =PROPER(TRIM(CLEAN(C31))) -> David Arnold | E31: 54 | F31: Female | G31: =PROPER(TRIM(CLEAN(F31))) -> Female | H31: East Jennifer | I31: =PROPER(TRIM(CLEAN(H31))) -> East Jennifer | J31: California | K31: =PROPER(TRIM(CLEAN(J31))) -> California | L31: USA | M31: =PROPER(TRIM(CLEAN(L31))) -> Usa | N31: Silver | O31: =IF(ISBLANK(N31), "Unknown",N31) -> Silver
A32: CUST1030 | B32: =PROPER(TRIM(CLEAN(A32))) -> Cust1030 | C32: Jessica Acevedo | D32: =PROPER(TRIM(CLEAN(C32))) -> Jessica Acevedo | E32: 64 | F32: Female | G32: =PROPER(TRIM(CLEAN(F32))) -> Female | H32: Amybury | I32: =PROPER(TRIM(CLEAN(H32))) -> Amybury | J32: Pennsylvania | K32: =PROPER(TRIM(CLEAN(J32))) -> Pennsylvania | L32: USA | M32: =PROPER(TRIM(CLEAN(L32))) -> Usa | N32: Bronze | O32: =IF(ISBLANK(N32), "Unknown",N32) -> Bronze
A33: CUST1031 | B33: =PROPER(TRIM(CLEAN(A33))) -> Cust1031 | C33: Sarah Vance | D33: =PROPER(TRIM(CLEAN(C33))) -> Sarah Vance | E33: 41 | F33: Male | G33: =PROPER(TRIM(CLEAN(F33))) -> Male | H33: Johnsonville | I33: =PROPER(TRIM(CLEAN(H33))) -> Johnsonville | J33: Oregon | K33: =PROPER(TRIM(CLEAN(J33))) -> Oregon | L33: USA | M33: =PROPER(TRIM(CLEAN(L33))) -> Usa | N33: Silver | O33: =IF(ISBLANK(N33), "Unknown",N33) -> Silver
A34: CUST1032 | B34: =PROPER(TRIM(CLEAN(A34))) -> Cust1032 | C34: Mike Jennings | D34: =PROPER(TRIM(CLEAN(C34))) -> Mike Jennings | E34: 48 | F34: Female | G34: =PROPER(TRIM(CLEAN(F34))) -> Female | H34: Fostermouth | I34: =PROPER(TRIM(CLEAN(H34))) -> Fostermouth | J34: Arizona | K34: =PROPER(TRIM(CLEAN(J34))) -> Arizona | L34: USA | M34: =PROPER(TRIM(CLEAN(L34))) -> Usa | N34: Gold | O34: =IF(ISBLANK(N34), "Unknown",N34) -> Gold
A35: CUST1033 | B35: =PROPER(TRIM(CLEAN(A35))) -> Cust1033 | C35: Robert Jones DDS | D35: =PROPER(TRIM(CLEAN(C35))) -> Robert Jones Dds | E35: 25 | F35: Male | G35: =PROPER(TRIM(CLEAN(F35))) -> Male | H35: Tristanton | I35: =PROPER(TRIM(CLEAN(H35))) -> Tristanton | J35: Oklahoma | K35: =PROPER(TRIM(CLEAN(J35))) -> Oklahoma | L35: USA | M35: =PROPER(TRIM(CLEAN(L35))) -> Usa | N35: Platinum | O35: =IF(ISBLANK(N35), "Unknown",N35) -> Platinum
A36: CUST1034 | B36: =PROPER(TRIM(CLEAN(A36))) -> Cust1034 | C36: Christopher Olson | D36: =PROPER(TRIM(CLEAN(C36))) -> Christopher Olson | E36: 27 | F36: Female | G36: =PROPER(TRIM(CLEAN(F36))) -> Female | H36: West Richard | I36: =PROPER(TRIM(CLEAN(H36))) -> West Richard | J36: Maryland | K36: =PROPER(TRIM(CLEAN(J36))) -> Maryland | L36: USA | M36: =PROPER(TRIM(CLEAN(L36))) -> Usa | N36: Platinum | O36: =IF(ISBLANK(N36), "Unknown",N36) -> Platinum
A37: CUST1035 | B37: =PROPER(TRIM(CLEAN(A37))) -> Cust1035 | C37: Rachel Myers | D37: =PROPER(TRIM(CLEAN(C37))) -> Rachel Myers | E37: 52 | F37: Male | G37: =PROPER(TRIM(CLEAN(F37))) -> Male | H37: Robertberg | I37: =PROPER(TRIM(CLEAN(H37))) -> Robertberg | J37: North Dakota | K37: =PROPER(TRIM(CLEAN(J37))) -> North Dakota | L37: USA | M37: =PROPER(TRIM(CLEAN(L37))) -> Usa | N37: Silver | O37: =IF(ISBLANK(N37), "Unknown",N37) -> Silver
A38: CUST1036 | B38: =PROPER(TRIM(CLEAN(A38))) -> Cust1036 | C38: Thomas Phillips | D38: =PROPER(TRIM(CLEAN(C38))) -> Thomas Phillips | E38: 20 | F38: Female | G38: =PROPER(TRIM(CLEAN(F38))) -> Female | H38: Luisfurt | I38: =PROPER(TRIM(CLEAN(H38))) -> Luisfurt | J38: Georgia | K38: =PROPER(TRIM(CLEAN(J38))) -> Georgia | L38: USA | M38: =PROPER(TRIM(CLEAN(L38))) -> Usa | N38: Gold | O38: =IF(ISBLANK(N38), "Unknown",N38) -> Gold
A39: CUST1037 | B39: =PROPER(TRIM(CLEAN(A39))) -> Cust1037 | C39: Christopher Carter | D39: =PROPER(TRIM(CLEAN(C39))) -> Christopher Carter | E39: 27 | F39: Female | G39: =PROPER(TRIM(CLEAN(F39))) -> Female | H39: Brendastad | I39: =PROPER(TRIM(CLEAN(H39))) -> Brendastad | J39: South Dakota | K39: =PROPER(TRIM(CLEAN(J39))) -> South Dakota | L39: USA | M39: =PROPER(TRIM(CLEAN(L39))) -> Usa | O39: =IF(ISBLANK(N39), "Unknown",N39) -> Unknown
A40: CUST1038 | B40: =PROPER(TRIM(CLEAN(A40))) -> Cust1038 | C40: Deanna Simpson | D40: =PROPER(TRIM(CLEAN(C40))) -> Deanna Simpson | E40: 35 | F40: Female | G40: =PROPER(TRIM(CLEAN(F40))) -> Female | H40: Brownport | I40: =PROPER(TRIM(CLEAN(H40))) -> Brownport | J40: North Dakota | K40: =PROPER(TRIM(CLEAN(J40))) -> North Dakota | L40: USA | M40: =PROPER(TRIM(CLEAN(L40))) -> Usa | N40: Bronze | O40: =IF(ISBLANK(N40), "Unknown",N40) -> Bronze
A41: CUST1039 | B41: =PROPER(TRIM(CLEAN(A41))) -> Cust1039 | C41: Tonya Reynolds | D41: =PROPER(TRIM(CLEAN(C41))) -> Tonya Reynolds | E41: 55 | F41: Female | G41: =PROPER(TRIM(CLEAN(F41))) -> Female | H41: Darleneton | I41: =PROPER(TRIM(CLEAN(H41))) -> Darleneton | J41: Michigan | K41: =PROPER(TRIM(CLEAN(J41))) -> Michigan | L41: USA | M41: =PROPER(TRIM(CLEAN(L41))) -> Usa | N41: Gold | O41: =IF(ISBLANK(N41), "Unknown",N41) -> Gold
A42: CUST1040 | B42: =PROPER(TRIM(CLEAN(A42))) -> Cust1040 | C42: Eric Vega | D42: =PROPER(TRIM(CLEAN(C42))) -> Eric Vega | E42: 50 | F42: Male | G42: =PROPER(TRIM(CLEAN(F42))) -> Male | H42: Williamsonland | I42: =PROPER(TRIM(CLEAN(H42))) -> Williamsonland | J42: Kansas | K42: =PROPER(TRIM(CLEAN(J42))) -> Kansas | L42: USA | M42: =PROPER(TRIM(CLEAN(L42))) -> Usa | N42: Gold | O42: =IF(ISBLANK(N42), "Unknown",N42) -> Gold
A43: CUST1041 | B43: =PROPER(TRIM(CLEAN(A43))) -> Cust1041 | C43: James Gibbs | D43: =PROPER(TRIM(CLEAN(C43))) -> James Gibbs | E43: 21 | F43: Male | G43: =PROPER(TRIM(CLEAN(F43))) -> Male | H43: Mooneyshire | I43: =PROPER(TRIM(CLEAN(H43))) -> Mooneyshire | J43: Alaska | K43: =PROPER(TRIM(CLEAN(J43))) -> Alaska | L43: USA | M43: =PROPER(TRIM(CLEAN(L43))) -> Usa | N43: Platinum | O43: =IF(ISBLANK(N43), "Unknown",N43) -> Platinum
A44: CUST1042 | B44: =PROPER(TRIM(CLEAN(A44))) -> Cust1042 | C44: William Martin | D44: =PROPER(TRIM(CLEAN(C44))) -> William Martin | E44: 19 | F44: Male | G44: =PROPER(TRIM(CLEAN(F44))) -> Male | H44: Ryanburgh | I44: =PROPER(TRIM(CLEAN(H44))) -> Ryanburgh | J44: Connecticut | K44: =PROPER(TRIM(CLEAN(J44))) -> Connecticut | L44: USA | M44: =PROPER(TRIM(CLEAN(L44))) -> Usa | N44: Platinum | O44: =IF(ISBLANK(N44), "Unknown",N44) -> Platinum
...

Sheet cleaned customer data
A1: Customer_ID | B1: name | C1: Age | D1: gender | E1: city | F1: state | G1: country | H1: loyalty level
A2: Cust1000 | B2: Sheena Bonilla | C2: 55 | D2: Male | E2: Donaldton | F2: North Carolina | G2: Usa | H2: Unknown
A3: Cust1001 | B3: Eugene Nelson | C3: 26 | D3: Female | E3: Phillipsmouth | F3: North Dakota | G3: Usa | H3: Platinum
A4: Cust1002 | B4: Dr. Benjamin Price | C4: 29 | D4: Female | E4: Kylebury | F4: Alabama | G4: Usa | H4: Platinum
A5: Cust1003 | B5: Jeremy Harris | C5: 59 | D5: Female | E5: Thomastown | F5: Ohio | G5: Usa | H5: Bronze
A6: Cust1004 | B6: Caroline Collins | C6: 64 | D6: Female | E6: Nicholasshire | F6: California | G6: Usa | H6: Silver
A7: Cust1005 | B7: Christine Vaughn | C7: 24 | D7: Male | E7: East Amandamouth | F7: Oregon | G7: Usa | H7: Bronze
A8: Cust1006 | B8: Amber Jackson | C8: 29 | D8: Female | E8: Deborahborough | F8: South Dakota | G8: Usa | H8: Platinum
A9: Cust1007 | B9: Daniel Boyd | C9: 29 | D9: Female | E9: West Pamelafurt | F9: West Virginia | G9: Usa | H9: Bronze
A10: Cust1008 | B10: Melissa Howard | C10: 53 | D10: Female | E10: Maynardton | F10: New Hampshire | G10: Usa | H10: Gold
A11: Cust1009 | B11: Ms. Maria Leach | C11: 64 | D11: Male | E11: Melissashire | F11: Pennsylvania | G11: Usa | H11: Platinum
A12: Cust1010 | B12: Dominic Page | C12: 53 | D12: Male | E12: Port Michaelburgh | F12: Pennsylvania | G12: Usa | H12: Bronze
A13: Cust1011 | B13: Brian Lopez | C13: 28 | D13: Female | E13: East Krista | F13: New York | G13: Usa | H13: Gold
... A501: Cust1499 | B501: Philip Pennington | C501: 27 | D501: Female | E501: East Valerieview | F501: Oregon | G501: Usa | H501: Platinum

Sheet Product_Dim
A1: Product_ID | B1: Product_Name | C1: Category | D1: Sub_Category | E1: Brand | F1: Cost | G1: Stock | H1: TOTAL COST | I1: TOTAL STOCK
A2: PROD0 | B2: Brother Laser Printer | C2: Electronics | D2: Computer | E2: Hunt Inc | F2: 112.42 | G2: 416 | H2: =IF(ISBLANK(F2),AVERAGE($F$2:$F$101),F2) -> 112.42 | I2: =IF(ISBLANK(G2),AVERAGE(G2:G101),G2) -> 416
A3: PROD1 | B3: Men's Graphic T-Shirt | C3: Clothing | D3: Tops | E3: Terry-Moore | F3: 342.56 | G3: 181 | H3: =IF(ISBLANK(F3),AVERAGE($F$2:$F$101),F3) -> 342.56 | I3: =IF(ISBLANK(G3),AVERAGE(G3:G102),G3) -> 181 | L3: 1. Sum, Count, and Average
A4: PROD10 | B4: Ceramic Kitchen Bowl Set | C4: Home | D4: Kitchen | E4: Hamilton Group | F4: 298.86 | G4: 308 | H4: =IF(ISBLANK(F4),AVERAGE($F$2:$F$101),F4) -> 298.86 | I4: =IF(ISBLANK(G4),AVERAGE(G4:G103),G4) -> 308 | L4: ● TOTAL NUMBER OF STOCK
A5: PROD11 | B5: HD Smart TV Stick | C5: Electronics | D5: Accessories | E5: Gibson, Hobbs and Weaver | F5: 449.4 | H5: =IF(ISBLANK(F5),AVERAGE($F$2:$F$101),F5) -> 449.4 | I5: =IF(ISBLANK(G5),AVERAGE(G5:G104),G5) -> 272.59574 | L5: =SUM(I2:I101) -> 27336.462 | M5: SUM(I2:I101)
A6: PROD12 | B6: Hair Strengthening Shampoo | C6: Beauty | D6: Beauty | E6: Rice LLC | F6: 115.82 | G6: 460 | H6: =IF(ISBLANK(F6),AVERAGE($F$2:$F$101),F6) -> 115.82 | I6: =IF(ISBLANK(G6),AVERAGE(G6:G105),G6) -> 460
A7: PROD13 | B7: USB-C Fast Charger | C7: Electronics | D7: Accessories | E7: Dawson-Perkins | F7: 242.23 | G7: 453 | H7: =IF(ISBLANK(F7),AVERAGE($F$2:$F$101),F7) -> 242.23 | I7: =IF(ISBLANK(G7),AVERAGE(G7:G106),G7) -> 453 | L7: ● TOTAL NUMBER OF PRODUCTS
A8: PROD14 | B8: Decorative Wall Mirror | C8: Home | D8: Decor | E8: Luna, Anderson and Bowman | F8: 48.01 | G8: 439 | H8: =IF(ISBLANK(F8),AVERAGE($F$2:$F$101),F8) -> 48.01 | I8: =IF(ISBLANK(G8),AVERAGE(G8:G107),G8) -> 439 | L8: =COUNTA(B2:B101) -> 100 | M8: COUNTA(B2:B101)
A9: PROD15 | B9: 4K Home Projector | C9: Electronics | D9: Appliances | E9: Thomas LLC | F9: 465.34 | G9: 301 | H9: =IF(ISBLANK(F9),AVERAGE($F$2:$F$101),F9) -> 465.34 | I9: =IF(ISBLANK(G9),AVERAGE(G9:G108),G9) -> 301
A10: PROD16 | B10: Beard Grooming Kit | C10: Beauty | D10: Grooming | E10: Erickson-Green | F10: 337.42 | G10: 256 | H10: =IF(ISBLANK(F10),AVERAGE($F$2:$F$101),F10) -> 337.42 | I10: =IF(ISBLANK(G10),AVERAGE(G10:G109),G10) -> 256 | L10: ● AVERAGE PRICE OF COST
A11: PROD17 | B11: Soccer Training Cone Set | C11: Sports | D11: Accessories | E11: Ford, Murphy and Wilson | F11: 144.53 | G11: 367 | H11: =IF(ISBLANK(F11),AVERAGE($F$2:$F$101),F11) -> 144.53 | I11: =IF(ISBLANK(G11),AVERAGE(G11:G110),G11) -> 367 | L11: =AVERAGE($F$2:$F$43) -> 240.66184 | M11: AVERAGE($F$2:$F$43)
A12: PROD18 | B12: Women's Denim Jeans | C12: Clothing | D12: Bottoms | E12: Guerra-Hendrix | G12: 343 | H12: =IF(ISBLANK(F12),AVERAGE($F$2:$F$101),F12) -> 254.04362 | I12: =IF(ISBLANK(G12),AVERAGE(G12:G111),G12) -> 343
A13: PROD19 | B13: Knee Support Brace | C13: Sports | D13: Equipment | E13: May-Reese | F13: 21.34 | G13: 65 | H13: =IF(ISBLANK(F13),AVERAGE($F$2:$F$101),F13) -> 21.34 | I13: =IF(ISBLANK(G13),AVERAGE(G13:G112),G13) -> 65 | L13: 2. Minimum and Maximum Values
A14: PROD2 | B14: Women's Casual Hoodie | C14: Clothing | D14: Outerwear | E14: Sims Inc | G14: 352 | H14: =IF(ISBLANK(F14),AVERAGE($F$2:$F$101),F14) -> 254.04362 | I14: =IF(ISBLANK(G14),AVERAGE(G14:G113),G14) -> 352 | L14: ● minimum price among all products.
A15: PROD20 | B15: Outdoor Sports Water Bottle | C15: Sports | D15: Accessories | E15: Soto-Ellis | F15: 131.51 | H15: =IF(ISBLANK(F15),AVERAGE($F$2:$F$101),F15) -> 131.51 | I15: =IF(ISBLANK(G15),AVERAGE(G15:G114),G15) -> 265.74118 | L15: =MIN(H2:H101) -> 17.31 | M15: MIN(H2:H101)
A16: PROD21 | B16: Multi-Purpose Storage Box | C16: Home | D16: Storage | E16: Gardner-Montes | F16: 123.46 | G16: 76 | H16: =IF(ISBLANK(F16),AVERAGE($F$2:$F$101),F16) -> 123.46 | I16: =IF(ISBLANK(G16),AVERAGE(G16:G115),G16) -> 76
A17: PROD22 | B17: Carbon Fiber Tennis Racket | C17: Sports | D17: Equipment | E17: Flores, Pineda and Rodriguez | F17: 484.62 | G17: 432 | H17: =IF(ISBLANK(F17),AVERAGE($F$2:$F$101),F17) -> 484.62 | I17: =IF(ISBLANK(G17),AVERAGE(G17:G116),G17) -> 432 | L17: ● maximum price among all products.
A18: PROD23 | B18: Men's Formal Shirt | C18: Clothing | D18: Tops | E18: Moon, Mora and Santos | G18: 360 | H18: =IF(ISBLANK(F18),AVERAGE($F$2:$F$101),F18) -> 254.04362 | I18: =IF(ISBLANK(G18),AVERAGE(G18:G117),G18) -> 360 | L18: =MAX(H2:H101) -> 495.72 | M18: MAX(H2:H101)
A19: PROD24 | B19: Foldable Camping Chair | C19: Sports | D19: Outdoor | E19: Cook Ltd | F19: 166.06 | G19: 340 | H19: =IF(ISBLANK(F19),AVERAGE($F$2:$F$101),F19) -> 166.06 | I19: =IF(ISBLANK(G19),AVERAGE(G19:G118),G19) -> 340
A20: PROD25 | B20: Women's Scarf Set | C20: Clothing | D20: Accessories | E20: Brown and Sons | F20: 174.02 | G20: 268 | H20: =IF(ISBLANK(F20),AVERAGE($F$2:$F$101),F20) -> 174.02 | I20: =IF(ISBLANK(G20),AVERAGE(G20:G119),G20) -> 268
A21: PROD26 | B21: Wireless Bluetooth Speaker | C21: Electronics | D21: Audio | E21: Reed-Schmidt | F21: 322.41 | G21: 213 | H21: =IF(ISBLANK(F21),AVERAGE($F$2:$F$101),F21) -> 322.41 | I21: =IF(ISBLANK(G21),AVERAGE(G21:G120),G21) -> 213 | L21: COST NEW | O21: STOCK NEW
A22: PROD27 | B22: Decorative Floor Vase | C22: Home | D22: Decor | E22: Khan, Jones and Paul | G22: 378 | H22: =IF(ISBLANK(F22),AVERAGE($F$2:$F$101),F22) -> 254.04362 | I22: =IF(ISBLANK(G22),AVERAGE(G22:G121),G22) -> 378
A23: PROD28 | B23: Sports Stopwatch Timer | C23: Sports | D23: Accessories | E23: Burns-Hansen | F23: 38.76 | G23: 137 | H23: =IF(ISBLANK(F23),AVERAGE($F$2:$F$101),F23) -> 38.76 | I23: =IF(ISBLANK(G23),AVERAGE(G23:G122),G23) -> 137 | L23: Mean | M23: 254.04362 | O23: Mean | P23: 273.36462
A24: PROD29 | B24: Fabric Sofa Throw Blanket | C24: Home | D24: Decor | E24: Hoffman Group | F24: 218.48 | G24: 276 | H24: =IF(ISBLANK(F24),AVERAGE($F$2:$F$101),F24) -> 218.48 | I24: =IF(ISBLANK(G24),AVERAGE(G24:G123),G24) -> 276 | L24: Standard Error | M24: 13.082031 | O24: Standard Error | P24: 12.995347
A25: PROD3 | B25: Men's Running Jacket | C25: Clothing | D25: Outerwear | E25: Pineda Ltd | F25: 364.67 | G25: 452 | H25: =IF(ISBLANK(F25),AVERAGE($F$2:$F$101),F25) -> 364.67 | I25: =IF(ISBLANK(G25),AVERAGE(G25:G124),G25) -> 452 | L25: Median | M25: 253.68681 | O25: Median | P25: 270.86037
A26: PROD30 | B26: Stainless Steel Cutlery Set | C26: Home | D26: Kitchen | E26: Stevens, Fernandez and Martin | F26: 19.52 | G26: 57 | H26: =IF(ISBLANK(F26),AVERAGE($F$2:$F$101),F26) -> 19.52 | I26: =IF(ISBLANK(G26),AVERAGE(G26:G125),G26) -> 57 | L26: Mode | M26: 254.04362 | O26: Mode | P26: 82
A27: PROD31 | B27: Basketball | C27: Sports | D27: Team Sports | E27: Nolan-Snow | F27: 204.39 | G27: 281 | H27: =IF(ISBLANK(F27),AVERAGE($F$2:$F$101),F27) -> 204.39 | I27: =IF(ISBLANK(G27),AVERAGE(G27:G126),G27) -> 281 | L27: Standard Deviation | M27: 130.82031 | O27: Standard Deviation | P27: 129.95347
A28: PROD32 | B28: Vitamin C Face Serum | C28: Beauty | D28: Skincare | E28: Griffin Ltd | F28: 283.83 | G28: 244 | H28: =IF(ISBLANK(F28),AVERAGE($F$2:$F$101),F28) -> 283.83 | I28: =IF(ISBLANK(G28),AVERAGE(G28:G127),G28) -> 244 | L28: Sample Variance | M28: 17113.953 | O28: Sample Variance | P28: 16887.905
A29: PROD33 | B29: Modern Wall Clock | C29: Home | D29: Decor | E29: Weiss-Watson | F29: 179.77 | G29: 305 | H29: =IF(ISBLANK(F29),AVERAGE($F$2:$F$101),F29) -> 179.77 | I29: =IF(ISBLANK(G29),AVERAGE(G29:G128),G29) -> 305 | L29: Kurtosis | M29: -0.94910645 | O29: Kurtosis | P29: -1.1531486
A30: PROD34 | B30: Gaming Mechanical Keyboard | C30: Electronics | D30: Computer | E30: Lucero LLC | F30: 419.28 | G30: 86 | H30: =IF(ISBLANK(F30),AVERAGE($F$2:$F$101),F30) -> 419.28 | I30: =IF(ISBLANK(G30),AVERAGE(G30:G129),G30) -> 86 | L30: Skewness | M30: 0.052318344 | O30: Skewness | P30: -0.0046257362
A31: PROD35 | B31: Bedroom Table Lamp | C31: Home | D31: Lighting | E31: Jones LLC | F31: 382.22 | G31: 329 | H31: =IF(ISBLANK(F31),AVERAGE($F$2:$F$101),F31) -> 382.22 | I31: =IF(ISBLANK(G31),AVERAGE(G31:G130),G31) -> 329 | L31: Range | M31: 478.41 | O31: Range | P31: 439
A32: PROD36 | B32: Women's Summer Dress | C32: Clothing | D32: Tops | E32: Smith-Mills | F32: 223.43 | G32: 154 | H32: =IF(ISBLANK(F32),AVERAGE($F$2:$F$101),F32) -> 223.43 | I32: =IF(ISBLANK(G32),AVERAGE(G32:G131),G32) -> 154 | L32: Minimum | M32: 17.31 | O32: Minimum | P32: 57
A33: PROD37 | B33: Men's Casual Sneakers | C33: Clothing | D33: Footwear | E33: Hogan-Lee | F33: 353.47 | G33: 214 | H33: =IF(ISBLANK(F33),AVERAGE($F$2:$F$101),F33) -> 353.47 | I33: =IF(ISBLANK(G33),AVERAGE(G33:G132),G33) -> 214 | L33: Maximum | M33: 495.72 | O33: Maximum | P33: 496
A34: PROD38 | B34: Sports Water Hydration Pack | C34: Sports | D34: Outdoor | E34: Sims-Smith | F34: 135.61 | G34: 394 | H34: =IF(ISBLANK(F34),AVERAGE($F$2:$F$101),F34) -> 135.61 | I34: =IF(ISBLANK(G34),AVERAGE(G34:G133),G34) -> 394 | L34: Sum | M34: 25404.362 | O34: Sum | P34: 27336.462
... A38: PROD41 | B38: Yoga Exercise Mat | C38: Sports | D38: Fitness | E38: Carroll, Long and Mendoza | F38: 313.26 | G38: 369 | H38: =IF(ISBLANK(F38),AVERAGE($F$2:$F$101),F38) -> 313.26 | I38: =IF(ISBLANK(G38),AVERAGE(G38:G137),G38) -> 369 | L38: Confidence Level(95.0%) | M38: 25.957588 | O38: Confidence Level(95.0%) | P38: 25.785588
A39: PROD42 | B39: Smart Home WiFi Camera | C39: Electronics | D39: Accessories | E39: Holmes LLC | F39: 450.71 | G39: 389 | H39: =IF(ISBLANK(F39),AVERAGE($F$2:$F$101),F39) -> 450.71 | I39: =IF(ISBLANK(G39),AVERAGE(G39:G138),G39) -> 389
A40: PROD43 | B40: USB External Hard Drive | C40: Electronics | D40: Computer | E40: Robinson Inc | F40: 253.33 | G40: 266 | H40: =IF(ISBLANK(F40),AVERAGE($F$2:$F$101),F40) -> 253.33 | I40: =IF(ISBLANK(G40),AVERAGE(G40:G139),G40) -> 266
A41: PROD44 | B41: Adjustable Jump Rope | C41: Sports | D41: Fitness | E41: Cox Inc | F41: 167.12 | G41: 316 | H41: =IF(ISBLANK(F41),AVERAGE($F$2:$F$101),F41) -> 167.12 | I41: =IF(ISBLANK(G41),AVERAGE(G41:G140),G41) -> 316
A42: PROD45 | B42: High-Grip Football | C42: Sports | D42: Team Sports | E42: Bridges, Banks and Cummings | F42: 318.91 | G42: 114 | H42: =IF(ISBLANK(F42),AVERAGE($F$2:$F$101),F42) -> 318.91 | I42: =IF(ISBLANK(G42),AVERAGE(G42:G141),G42) -> 114
A43: PROD46 | B43: Men's Winter Jacket | C43: Clothing | D43: Outerwear | E43: Kelly, Smith and Perez | F43: 167.34 | G43: 296 | H43: =IF(ISBLANK(F43),AVERAGE($F$2:$F$101),F43) -> 167.34 | I43: =IF(ISBLANK(G43),AVERAGE(G43:G142),G43) -> 296
...

Sheet Store_Dim
A1: Store_ID | B1: Store_Name | C1: Region | D1: City | E1: Store_Type
A2: STORE0 | B2: Rivera-Warner | C2: East | D2: Washingtonfurt | E2: Flagship
A3: STORE1 | B3: Martinez, Adkins and Johnson | C3: North | D3: Danielmouth | E3: Flagship
A4: STORE2 | B4: Black-Horn | C4: South | D4: North Nancyview | E4: Outlet
A5: STORE3 | B5: Johnson-Wright | C5: North | D5: Hoodberg | E5: Outlet
A6: STORE4 | B6: Alexander Group | C6: South | D6: Port Sharon | E6: Online
A7: STORE5 | B7: Gray Ltd | C7: North | D7: New Michaelchester | E7: Outlet
A8: STORE6 | B8: Benson-Elliott | C8: East | D8: Port Josephberg | E8: Online
A9: STORE7 | B9: Martinez-Mullins | C9: South | D9: Williamsfurt | E9: Online
A10: STORE8 | B10: Bean, Jones and Park | C10: West | D10: Thompsonborough | E10: Online
A11: STORE9 | B11: Moore, Padilla and Butler | C11: South | D11: East Johnstad | E11: Flagship
A12: STORE10 | B12: Hill, Wagner and Ballard | C12: East | D12: East Davidville | E12: Online
... A21: STORE19 | B21: Mann-Austin | C21: East | D21: Vasquezborough | E21: Online

Sheet region vs store vs rev
A3: Sum of TOTAL REVENUE | B3: Column Labels
A4: Row Labels | B4: East | C4: North | D4: South | E4: West | F4: Grand Total
A5: STORE0 | B5: 97145.53 | F5: 97145.53
A6: STORE1 | C6: 114592.9 | F6: 114592.9
A7: STORE10 | B7: 129840.12 | F7: 129840.12
A8: STORE11 | D8: 109128.64 | F8: 109128.64
A9: STORE12 | C9: 138711.99 | F9: 138711.99
A10: STORE13 | B10: 137594.27 | F10: 137594.27
A11: STORE14 | D11: 122885.99 | F11: 122885.99
A12: STORE15 | C12: 117454.96 | F12: 117454.96
A13: STORE16 | E13: 131216.55 | F13: 131216.55
A14: STORE17 | C14: 143833.83 | F14: 143833.83
A15: STORE18 | B15: 123258.38 | F15: 123258.38
A16: STORE19 | B16: 109963.71 | F16: 109963.71
A17: STORE2 | D17: 116155.4 | F17: 116155.4
A18: STORE3 | C18: 147511.15 | F18: 147511.15
A19: STORE4 | D19: 144009.6 | F19: 144009.6
A20: STORE5 | C20: 95366.36 | F20: 95366.36
A21: STORE6 | B21: 134996.89 | F21: 134996.89
A22: STORE7 | D22: 125499.33 | F22: 125499.33
A23: STORE8 | E23: 185351.39 | F23: 185351.39
A24: STORE9 | D24: 126549.98 | F24: 126549.98
A25: Grand Total | B25: 732798.91 | C25: 757471.19 | D25: 744228.94 | E25: 316567.94 | F25: 2551067

Sheet Sales_Fact
A1: Sales_ID | B1: Order_Date | C1: Customer_ID | D1: Product_ID | E1: Store_ID | F1: Quantity | G1: FILLED QT | H1: Unit_Price | I1: UP | J1: Discount | K1: DIS | L1: Payment_Type | M1: Total_Amount | N1: TOTAL REVENUE | O1: REGION
A2: SALE0 | B2: 45480 | C2: CUST1409 | D2: PROD97 | E2: STORE3 | F2: 1 | G2: =IF(F2="",1,F2) -> 1 | H2: 218.04 | I2: =IF(ISBLANK(H2),AVERAGE($H$2:$H$2001),H2) -> 218.04 | J2: 0.09 | K2: =IF(ISBLANK(J2),AVERAGE($J$2:$J$2001),J2) -> 0.09 | L2: Credit Card | M2: 198.4164 | N2: =(I2*G2)-J2 -> 217.95 | O2: =VLOOKUP(E2,Store_Dim!$A$1:$E$21,3,FALSE) -> North
A3: SALE1 | B3: 45285 | C3: CUST1467 | D3: PROD74 | E3: STORE17 | F3: 3 | G3: =IF(F3="",1,F3) -> 3 | H3: 104.47 | I3: =IF(ISBLANK(H3),AVERAGE($H$2:$H$2001),H3) -> 104.47 | J3: 0.27 | K3: =IF(ISBLANK(J3),AVERAGE($J$2:$J$2001),J3) -> 0.27 | L3: PayPal | M3: 228.7893 | N3: =(I3*G3)-J3 -> 313.14 | O3: =VLOOKUP(E3,Store_Dim!$A$1:$E$21,3,FALSE) -> North
A4: SALE2 | B4: 45446 | C4: CUST1056 | D4: PROD49 | E4: STORE8 | F4: 4 | G4: =IF(F4="",1,F4) -> 4 | H4: 914.05 | I4: =IF(ISBLANK(H4),AVERAGE($H$2:$H$2001),H4) -> 914.05 | J4: 0.25 | K4: =IF(ISBLANK(J4),AVERAGE($J$2:$J$2001),J4) -> 0.25 | L4: Credit Card | M4: 2742.15 | N4: =(I4*G4)-J4 -> 3655.95 | O4: =VLOOKUP(E4,Store_Dim!$A$1:$E$21,3,FALSE) -> West | P4: 4. Conditional Functions – SUMIF and COUNTIF
A5: SALE3 | B5: 45259 | C5: CUST1346 | D5: PROD76 | E5: STORE8 | F5: 1 | G5: =IF(F5="",1,F5) -> 1 | H5: 921.51 | I5: =IF(ISBLANK(H5),AVERAGE($H$2:$H$2001),H5) -> 921.51 | J5: 0.16 | K5: =IF(ISBLANK(J5),AVERAGE($J$2:$J$2001),J5) -> 0.16 | L5: COD | M5: 774.0684 | N5: =(I5*G5)-J5 -> 921.35 | O5: =VLOOKUP(E5,Store_Dim!$A$1:$E$21,3,FALSE) -> West | P5: ● Use the SUMIF function to calculate the total amount in credit card payment type
A6: SALE4 | B6: 45297 | C6: CUST1493 | D6: PROD59 | E6: STORE5 | F6: 3 | G6: =IF(F6="",1,F6) -> 3 | H6: 745.3 | I6: =IF(ISBLANK(H6),AVERAGE($H$2:$H$2001),H6) -> 745.3 | J6: 0.18 | K6: =IF(ISBLANK(J6),AVERAGE($J$2:$J$2001),J6) -> 0.18 | L6: Credit Card | M6: 1833.438 | N6: =(I6*G6)-J6 -> 2235.72 | O6: =VLOOKUP(E6,Store_Dim!$A$1:$E$21,3,FALSE) -> North
A7: SALE5 | B7: 45499 | C7: CUST1116 | D7: PROD15 | E7: STORE7 | F7: 3 | G7: =IF(F7="",1,F7) -> 3 | H7: 147.01 | I7: =IF(ISBLANK(H7),AVERAGE($H$2:$H$2001),H7) -> 147.01 | J7: 0.19 | K7: =IF(ISBLANK(J7),AVERAGE($J$2:$J$2001),J7) -> 0.19 | L7: COD | M7: 357.2343 | N7: =(I7*G7)-J7 -> 440.84 | O7: =VLOOKUP(E7,Store_Dim!$A$1:$E$21,3,FALSE) -> South | P7: =SUMIF(L2:L2001,"Credit Card",M2:M2001) -> 713754.93 | Q7: SUMIF(L2:L2001,"Credit Card",M2:M2001)
A8: SALE6 | B8: 45850 | C8: CUST1016 | D8: PROD56 | E8: STORE4 | F8: 2 | G8: =IF(F8="",1,F8) -> 2 | H8: 785.31 | I8: =IF(ISBLANK(H8),AVERAGE($H$2:$H$2001),H8) -> 785.31 | J8: 0.15 | K8: =IF(ISBLANK(J8),AVERAGE($J$2:$J$2001),J8) -> 0.15 | L8: PayPal | M8: 1335.027 | N8: =(I8*G8)-J8 -> 1570.47 | O8: =VLOOKUP(E8,Store_Dim!$A$1:$E$21,3,FALSE) -> South | P8: =SUM(SALES_FACT[TOTAL REVENUE]) -> 2551067 | Q8: TOTAL REVENUE
A9: SALE7 | B9: 45248 | C9: CUST1152 | D9: PROD70 | E9: STORE8 | F9: 4 | G9: =IF(F9="",1,F9) -> 4 | H9: 342.39 | I9: =IF(ISBLANK(H9),AVERAGE($H$2:$H$2001),H9) -> 342.39 | J9: 0.23 | K9: =IF(ISBLANK(J9),AVERAGE($J$2:$J$2001),J9) -> 0.23 | L9: PayPal | M9: 1054.5612 | N9: =(I9*G9)-J9 -> 1369.33 | O9: =VLOOKUP(E9,Store_Dim!$A$1:$E$21,3,FALSE) -> West | P9: USING SUM IF CALTULATING THE REGION BASED REVENUE
A10: SALE8 | B10: 45781 | C10: CUST1187 | D10: PROD99 | E10: STORE5 | G10: =IF(F10="",1,F10) -> 1 | H10: 448.25 | I10: =IF(ISBLANK(H10),AVERAGE($H$2:$H$2001),H10) -> 448.25 | J10: 0.07 | K10: =IF(ISBLANK(J10),AVERAGE($J$2:$J$2001),J10) -> 0.07 | L10: PayPal | M10: 1250.6175 | N10: =(I10*G10)-J10 -> 448.18 | O10: =VLOOKUP(E10,Store_Dim!$A$1:$E$21,3,FALSE) -> North
A11: SALE9 | B11: 45869 | C11: CUST1464 | D11: PROD33 | E11: STORE0 | F11: 2 | G11: =IF(F11="",1,F11) -> 2 | H11: 873.17 | I11: =IF(ISBLANK(H11),AVERAGE($H$2:$H$2001),H11) -> 873.17 | J11: 0.23 | K11: =IF(ISBLANK(J11),AVERAGE($J$2:$J$2001),J11) -> 0.23 | L11: PayPal | M11: 1344.6818 | N11: =(I11*G11)-J11 -> 1746.11 | O11: =VLOOKUP(E11,Store_Dim!$A$1:$E$21,3,FALSE) -> East | P11: =SUMIF(O2:O2001,"North",N2:N2001) -> 757471.19 | Q11: SUMIF(O2:O2001,"North",N2:N2001)
A12: SALE10 | B12: 45335 | C12: CUST1065 | D12: PROD24 | E12: STORE14 | F12: 1 | G12: =IF(F12="",1,F12) -> 1 | H12: 278.63 | I12: =IF(ISBLANK(H12),AVERAGE($H$2:$H$2001),H12) -> 278.63 | J12: 0.07 | K12: =IF(ISBLANK(J12),AVERAGE($J$2:$J$2001),J12) -> 0.07 | L12: Credit Card | M12: 259.1259 | N12: =(I12*G12)-J12 -> 278.56 | O12: =VLOOKUP(E12,Store_Dim!$A$1:$E$21,3,FALSE) -> South | P12: =SUMIF(O2:O2001,"West",N2:N2001) -> 316567.94 | Q12: SUMIF(O2:O2001,"West",N2:N2001)
A13: SALE11 | B13: 45801 | C13: CUST1320 | D13: PROD39 | E13: STORE1 | F13: 4 | G13: =IF(F13="",1,F13) -> 4 | H13: 286.92 | I13: =IF(ISBLANK(H13),AVERAGE($H$2:$H$2001),H13) -> 286.92 | J13: 0.17 | K13: =IF(ISBLANK(J13),AVERAGE($J$2:$J$2001),J13) -> 0.17 | L13: Credit Card | M13: 952.5744 | N13: =(I13*G13)-J13 -> 1147.51 | O13: =VLOOKUP(E13,Store_Dim!$A$1:$E$21,3,FALSE) -> North | P13: =SUMIF(O2:O2001,"South",N2:N2001) -> 744228.94 | Q13: SUMIF(O2:O2001,"South",N2:N2001)
A14: SALE12 | B14: 45528 | C14: CUST1237 | D14: PROD88 | E14: STORE4 | F14: 4 | G14: =IF(F14="",1,F14) -> 4 | H14: 644.58 | I14: =IF(ISBLANK(H14),AVERAGE($H$2:$H$2001),H14) -> 644.58 | J14: 0.01 | K14: =IF(ISBLANK(J14),AVERAGE($J$2:$J$2001),J14) -> 0.01 | L14: Credit Card | M14: 2552.5368 | N14: =(I14*G14)-J14 -> 2578.31 | O14: =VLOOKUP(E14,Store_Dim!$A$1:$E$21,3,FALSE) -> South | P14: =SUMIF(O2:O2001,"East",N2:N2001) -> 732798.91 | Q14: SUMIF(O2:O2001,"East",N2:N2001)
A15: SALE13 | B15: 45875 | C15: CUST1443 | D15: PROD34 | E15: STORE16 | F15: 2 | G15: =IF(F15="",1,F15) -> 2 | H15: 316.9 | I15: =IF(ISBLANK(H15),AVERAGE($H$2:$H$2001),H15) -> 316.9 | J15: 0.3 | K15: =IF(ISBLANK(J15),AVERAGE($J$2:$J$2001),J15) -> 0.3 | L15: PayPal | M15: 443.66 | N15: =(I15*G15)-J15 -> 633.5 | O15: =VLOOKUP(E15,Store_Dim!$A$1:$E$21,3,FALSE) -> West
A16: SALE14 | B16: 45829 | C16: CUST1348 | D16: PROD24 | E16: STORE15 | F16: 4 | G16: =IF(F16="",1,F16) -> 4 | H16: 403.47 | I16: =IF(ISBLANK(H16),AVERAGE($H$2:$H$2001),H16) -> 403.47 | J16: 0.29 | K16: =IF(ISBLANK(J16),AVERAGE($J$2:$J$2001),J16) -> 0.29 | L16: PayPal | M16: 1145.8548 | N16: =(I16*G16)-J16 -> 1613.59 | O16: =VLOOKUP(E16,Store_Dim!$A$1:$E$21,3,FALSE) -> North | P16: ● Using COUNTIF function seprating the value less than and greater than in unit price
A17: SALE15 | B17: 45636 | C17: CUST1435 | D17: PROD36 | E17: STORE9 | G17: =IF(F17="",1,F17) -> 1 | H17: 871.34 | I17: =IF(ISBLANK(H17),AVERAGE($H$2:$H$2001),H17) -> 871.34 | J17: 0.04 | K17: =IF(ISBLANK(J17),AVERAGE($J$2:$J$2001),J17) -> 0.04 | L17: COD | M17: 2509.4592 | N17: =(I17*G17)-J17 -> 871.3 | O17: =VLOOKUP(E17,Store_Dim!$A$1:$E$21,3,FALSE) -> South
A18: SALE16 | B18: 45913 | C18: CUST1276 | D18: PROD65 | E18: STORE19 | F18: 2 | G18: =IF(F18="",1,F18) -> 2 | H18: 451.98 | I18: =IF(ISBLANK(H18),AVERAGE($H$2:$H$2001),H18) -> 451.98 | J18: 0.25 | K18: =IF(ISBLANK(J18),AVERAGE($J$2:$J$2001),J18) -> 0.25 | L18: Credit Card | M18: 677.97 | N18: =(I18*G18)-J18 -> 903.71 | O18: =VLOOKUP(E18,Store_Dim!$A$1:$E$21,3,FALSE) -> East | P18: =COUNTIF(H2:H2001,"<500") -> 956 | Q18: COUNTIF(H2:H2001,"<500")
A19: SALE17 | B19: 45637 | C19: CUST1079 | D19: PROD27 | E19: STORE4 | F19: 2 | G19: =IF(F19="",1,F19) -> 2 | H19: 502.69 | I19: =IF(ISBLANK(H19),AVERAGE($H$2:$H$2001),H19) -> 502.69 | J19: 0.23 | K19: =IF(ISBLANK(J19),AVERAGE($J$2:$J$2001),J19) -> 0.23 | L19: Credit Card | M19: 774.1426 | N19: =(I19*G19)-J19 -> 1005.15 | O19: =VLOOKUP(E19,Store_Dim!$A$1:$E$21,3,FALSE) -> South | P19: =COUNTIF(H2:H2001,">500") -> 1041 | Q19: COUNTIF(H2:H2001,">500")
A20: SALE18 | B20: 45517 | C20: CUST1094 | D20: PROD39 | E20: STORE4 | F20: 2 | G20: =IF(F20="",1,F20) -> 2 | H20: 559.23 | I20: =IF(ISBLANK(H20),AVERAGE($H$2:$H$2001),H20) -> 559.23 | J20: 0.25 | K20: =IF(ISBLANK(J20),AVERAGE($J$2:$J$2001),J20) -> 0.25 | L20: COD | M20: 838.845 | N20: =(I20*G20)-J20 -> 1118.21 | O20: =VLOOKUP(E20,Store_Dim!$A$1:$E$21,3,FALSE) -> South
A21: SALE19 | B21: 45369 | C21: CUST1239 | D21: PROD60 | E21: STORE13 | F21: 4 | G21: =IF(F21="",1,F21) -> 4 | I21: =IF(ISBLANK(H21),AVERAGE($H$2:$H$2001),H21) -> 513.98477 | J21: 0.04 | K21: =IF(ISBLANK(J21),AVERAGE($J$2:$J$2001),J21) -> 0.04 | L21: COD | M21: 1782.4512 | N21: =(I21*G21)-J21 -> 2055.8991 | O21: =VLOOKUP(E21,Store_Dim!$A$1:$E$21,3,FALSE) -> East
A22: SALE20 | B22: 45843 | C22: CUST1144 | D22: PROD72 | E22: STORE17 | F22: 3 | G22: =IF(F22="",1,F22) -> 3 | H22: 986.04 | I22: =IF(ISBLANK(H22),AVERAGE($H$2:$H$2001),H22) -> 986.04 | J22: 0.27 | K22: =IF(ISBLANK(J22),AVERAGE($J$2:$J$2001),J22) -> 0.27 | L22: COD | M22: 2159.4276 | N22: =(I22*G22)-J22 -> 2957.85 | O22: =VLOOKUP(E22,Store_Dim!$A$1:$E$21,3,FALSE) -> North
A23: SALE21 | B23: 45447 | C23: CUST1396 | D23: PROD43 | E23: STORE18 | F23: 1 | G23: =IF(F23="",1,F23) -> 1 | H23: 589.56 | I23: =IF(ISBLANK(H23),AVERAGE($H$2:$H$2001),H23) -> 589.56 | J23: 0.22 | K23: =IF(ISBLANK(J23),AVERAGE($J$2:$J$2001),J23) -> 0.22 | L23: Credit Card | M23: 459.8568 | N23: =(I23*G23)-J23 -> 589.34 | O23: =VLOOKUP(E23,Store_Dim!$A$1:$E$21,3,FALSE) -> East
A24: SALE22 | B24: 45394 | C24: CUST1476 | D24: PROD69 | E24: STORE10 | F24: 3 | G24: =IF(F24="",1,F24) -> 3 | H24: 979.42 | I24: =IF(ISBLANK(H24),AVERAGE($H$2:$H$2001),H24) -> 979.42 | J24: 0.03 | K24: =IF(ISBLANK(J24),AVERAGE($J$2:$J$2001),J24) -> 0.03 | L24: PayPal | M24: 2850.1122 | N24: =(I24*G24)-J24 -> 2938.23 | O24: =VLOOKUP(E24,Store_Dim!$A$1:$E$21,3,FALSE) -> East
A25: SALE23 | B25: 45466 | C25: CUST1368 | D25: PROD12 | E25: STORE8 | F25: 1 | G25: =IF(F25="",1,F25) -> 1 | H25: 719.28 | I25: =IF(ISBLANK(H25),AVERAGE($H$2:$H$2001),H25) -> 719.28 | J25: 0.08 | K25: =IF(ISBLANK(J25),AVERAGE($J$2:$J$2001),J25) -> 0.08 | L25: Credit Card | M25: 661.7376 | N25: =(I25*G25)-J25 -> 719.2 | O25: =VLOOKUP(E25,Store_Dim!$A$1:$E$21,3,FALSE) -> West
A26: SALE24 | B26: 45908 | C26: CUST1186 | D26: PROD67 | E26: STORE6 | F26: 3 | G26: =IF(F26="",1,F26) -> 3 | H26: 77.6 | I26: =IF(ISBLANK(H26),AVERAGE($H$2:$H$2001),H26) -> 77.6 | J26: 0.07 | K26: =IF(ISBLANK(J26),AVERAGE($J$2:$J$2001),J26) -> 0.07 | L26: Credit Card | M26: 216.504 | N26: =(I26*G26)-J26 -> 232.73 | O26: =VLOOKUP(E26,Store_Dim!$A$1:$E$21,3,FALSE) -> East
A27: SALE25 | B27: 45552 | C27: CUST1381 | D27: PROD5 | E27: STORE3 | F27: 4 | G27: =IF(F27="",1,F27) -> 4 | H27: 852.71 | I27: =IF(ISBLANK(H27),AVERAGE($H$2:$H$2001),H27) -> 852.71 | J27: 0.14 | K27: =IF(ISBLANK(J27),AVERAGE($J$2:$J$2001),J27) -> 0.14 | L27: PayPal | M27: 2933.3224 | N27: =(I27*G27)-J27 -> 3410.7 | O27: =VLOOKUP(E27,Store_Dim!$A$1:$E$21,3,FALSE) -> North
A28: SALE26 | B28: 45294 | C28: CUST1213 | D28: PROD98 | E28: STORE8 | F28: 4 | G28: =IF(F28="",1,F28) -> 4 | H28: 156.16 | I28: =IF(ISBLANK(H28),AVERAGE($H$2:$H$2001),H28) -> 156.16 | K28: =IF(ISBLANK(J28),AVERAGE($J$2:$J$2001),J28) -> 0.14808617 | L28: Credit Card | M28: 599.6544 | N28: =(I28*G28)-J28 -> 624.64 | O28: =VLOOKUP(E28,Store_Dim!$A$1:$E$21,3,FALSE) -> West
A29: SALE27 | B29: 45710 | C29: CUST1200 | D29: PROD77 | E29: STORE8 | F29: 3 | G29: =IF(F29="",1,F29) -> 3 | H29: 815.49 | I29: =IF(ISBLANK(H29),AVERAGE($H$2:$H$2001),H29) -> 815.49 | J29: 0.17 | K29: =IF(ISBLANK(J29),AVERAGE($J$2:$J$2001),J29) -> 0.17 | L29: Credit Card | M29: 2030.5701 | N29: =(I29*G29)-J29 -> 2446.3 | O29: =VLOOKUP(E29,Store_Dim!$A$1:$E$21,3,FALSE) -> West
A30: SALE28 | B30: 45923 | C30: CUST1148 | D30: PROD13 | E30: STORE2 | F30: 2 | G30: =IF(F30="",1,F30) -> 2 | H30: 74.21 | I30: =IF(ISBLANK(H30),AVERAGE($H$2:$H$2001),H30) -> 74.21 | J30: 0.11 | K30: =IF(ISBLANK(J30),AVERAGE($J$2:$J$2001),J30) -> 0.11 | L30: PayPal | M30: 132.0938 | N30: =(I30*G30)-J30 -> 148.31 | O30: =VLOOKUP(E30,Store_Dim!$A$1:$E$21,3,FALSE) -> South
A31: SALE29 | B31: 45302 | C31: CUST1348 | D31: PROD99 | E31: STORE3 | G31: =IF(F31="",1,F31) -> 1 | H31: 451.67 | I31: =IF(ISBLANK(H31),AVERAGE($H$2:$H$2001),H31) -> 451.67 | J31: 0.15 | K31: =IF(ISBLANK(J31),AVERAGE($J$2:$J$2001),J31) -> 0.15 | L31: Credit Card | M31: 1535.678 | N31: =(I31*G31)-J31 -> 451.52 | O31: =VLOOKUP(E31,Store_Dim!$A$1:$E$21,3,FALSE) -> North
A32: SALE30 | B32: 45217 | C32: CUST1028 | D32: PROD5 | E32: STORE19 | F32: 1 | G32: =IF(F32="",1,F32) -> 1 | H32: 429.38 | I32: =IF(ISBLANK(H32),AVERAGE($H$2:$H$2001),H32) -> 429.38 | J32: 0.13 | K32: =IF(ISBLANK(J32),AVERAGE($J$2:$J$2001),J32) -> 0.13 | L32: PayPal | M32: 373.5606 | N32: =(I32*G32)-J32 -> 429.25 | O32: =VLOOKUP(E32,Store_Dim!$A$1:$E$21,3,FALSE) -> East
A33: SALE31 | B33: 45593 | C33: CUST1412 | D33: PROD53 | E33: STORE12 | F33: 2 | G33: =IF(F33="",1,F33) -> 2 | H33: 148.96 | I33: =IF(ISBLANK(H33),AVERAGE($H$2:$H$2001),H33) -> 148.96 | J33: 0.03 | K33: =IF(ISBLANK(J33),AVERAGE($J$2:$J$2001),J33) -> 0.03 | L33: COD | M33: 288.9824 | N33: =(I33*G33)-J33 -> 297.89 | O33: =VLOOKUP(E33,Store_Dim!$A$1:$E$21,3,FALSE) -> North
A34: SALE32 | B34: 45597 | C34: CUST1398 | D34: PROD75 | E34: STORE8 | F34: 4 | G34: =IF(F34="",1,F34) -> 4 | H34: 313.83 | I34: =IF(ISBLANK(H34),AVERAGE($H$2:$H$2001),H34) -> 313.83 | J34: 0.08 | K34: =IF(ISBLANK(J34),AVERAGE($J$2:$J$2001),J34) -> 0.08 | L34: Credit Card | M34: 1154.8944 | N34: =(I34*G34)-J34 -> 1255.24 | O34: =VLOOKUP(E34,Store_Dim!$A$1:$E$21,3,FALSE) -> West
A35: SALE33 | B35: 45620 | C35: CUST1453 | D35: PROD12 | E35: STORE6 | F35: 2 | G35: =IF(F35="",1,F35) -> 2 | H35: 717.31 | I35: =IF(ISBLANK(H35),AVERAGE($H$2:$H$2001),H35) -> 717.31 | J35: 0.15 | K35: =IF(ISBLANK(J35),AVERAGE($J$2:$J$2001),J35) -> 0.15 | L35: Credit Card | M35: 1219.427 | N35: =(I35*G35)-J35 -> 1434.47 | O35: =VLOOKUP(E35,Store_Dim!$A$1:$E$21,3,FALSE) -> East
A36: SALE34 | B36: 45215 | C36: CUST1344 | D36: PROD79 | E36: STORE1 | G36: =IF(F36="",1,F36) -> 1 | H36: 873.22 | I36: =IF(ISBLANK(H36),AVERAGE($H$2:$H$2001),H36) -> 873.22 | J36: 0.18 | K36: =IF(ISBLANK(J36),AVERAGE($J$2:$J$2001),J36) -> 0.18 | L36: Credit Card | M36: 2148.1212 | N36: =(I36*G36)-J36 -> 873.04 | O36: =VLOOKUP(E36,Store_Dim!$A$1:$E$21,3,FALSE) -> North
A37: SALE35 | B37: 45878 | C37: CUST1218 | D37: PROD16 | E37: STORE3 | F37: 4 | G37: =IF(F37="",1,F37) -> 4 | H37: 109.36 | I37: =IF(ISBLANK(H37),AVERAGE($H$2:$H$2001),H37) -> 109.36 | J37: 0.19 | K37: =IF(ISBLANK(J37),AVERAGE($J$2:$J$2001),J37) -> 0.19 | L37: COD | M37: 354.3264 | N37: =(I37*G37)-J37 -> 437.25 | O37: =VLOOKUP(E37,Store_Dim!$A$1:$E$21,3,FALSE) -> North
A38: SALE36 | B38: 45635 | C38: CUST1086 | D38: PROD5 | E38: STORE7 | F38: 3 | G38: =IF(F38="",1,F38) -> 3 | H38: 559.52 | I38: =IF(ISBLANK(H38),AVERAGE($H$2:$H$2001),H38) -> 559.52 | J38: 0.16 | K38: =IF(ISBLANK(J38),AVERAGE($J$2:$J$2001),J38) -> 0.16 | L38: PayPal | M38: 1409.9904 | N38: =(I38*G38)-J38 -> 1678.4 | O38: =VLOOKUP(E38,Store_Dim!$A$1:$E$21,3,FALSE) -> South
A39: SALE37 | B39: 45329 | C39: CUST1492 | D39: PROD10 | E39: STORE17 | F39: 3 | G39: =IF(F39="",1,F39) -> 3 | H39: 121.76 | I39: =IF(ISBLANK(H39),AVERAGE($H$2:$H$2001),H39) -> 121.76 | J39: 0.27 | K39: =IF(ISBLANK(J39),AVERAGE($J$2:$J$2001),J39) -> 0.27 | L39: PayPal | M39: 266.6544 | N39: =(I39*G39)-J39 -> 365.01 | O39: =VLOOKUP(E39,Store_Dim!$A$1:$E$21,3,FALSE) -> North
A40: SALE38 | B40: 45378 | C40: CUST1189 | D40: PROD33 | E40: STORE13 | F40: 4 | G40: =IF(F40="",1,F40) -> 4 | H40: 735.32 | I40: =IF(ISBLANK(H40),AVERAGE($H$2:$H$2001),H40) -> 735.32 | J40: 0.06 | K40: =IF(ISBLANK(J40),AVERAGE($J$2:$J$2001),J40) -> 0.06 | L40: COD | M40: 2764.8032 | N40: =(I40*G40)-J40 -> 2941.22 | O40: =VLOOKUP(E40,Store_Dim!$A$1:$E$21,3,FALSE) -> East
...

Sheet GENDER VS LOYALTY LEVEL
A3: Row Labels | B3: Count of Age
A4: Bronze | B4: 125
A5: Female | B5: 60
A6: Male | B6: 65
A7: Gold | B7: 122
A8: Female | B8: 68
A9: Male | B9: 54
A10: Platinum | B10: 145
A11: Female | B11: 82
A12: Male | B12: 63
A13: Silver | B13: 104
A14: Female | B14: 51
A15: Male | B15: 53
... A19: Grand Total | B19: 500

Sheet product vs dis vs quty
A3: Row Labels | B3: DST | C3: QUA
A4: PROD0 | B4: 2.21 | C4: 39
A5: PROD1 | B5: 1.95 | C5: 41
A6: PROD10 | B6: 3.42 | C6: 51
A7: PROD11 | B7: 3.37 | C7: 53
A8: PROD12 | B8: 2.54 | C8: 41
A9: PROD13 | B9: 2.96 | C9: 55
A10: PROD14 | B10: 1.95 | C10: 45
A11: PROD15 | B11: 4.2480862 | C11: 72
A12: PROD16 | B12: 2.81 | C12: 62
A13: PROD17 | B13: 3.7 | C13: 70
A14: PROD18 | B14: 2.33 | C14: 37
A15: PROD19 | B15: 3.55 | C15: 63
... A104: Grand Total | B104: 296.17234 | C104: 4953

Sheet STORE VS REV VS QUN
A3: Row Labels | B3: Sum of TOTAL REVENUE | C3: Sum of Quantity
A4: STORE0 | B4: 97145.53 | C4: 204
A5: STORE1 | B5: 114592.9 | C5: 229
A6: STORE10 | B6: 129840.12 | C6: 255
A7: STORE11 | B7: 109128.64 | C7: 206
A8: STORE12 | B8: 138711.99 | C8: 259
A9: STORE13 | B9: 137594.27 | C9: 243
A10: STORE14 | B10: 122885.99 | C10: 224
A11: STORE15 | B11: 117454.96 | C11: 243
A12: STORE16 | B12: 131216.55 | C12: 249
A13: STORE17 | B13: 143833.83 | C13: 274
A14: STORE18 | B14: 123258.38 | C14: 247
A15: STORE19 | B15: 109963.71 | C15: 240
... A24: Grand Total | B24: 2551067 | C24: 4948

Sheet REGION VS QT & DIS
A3: REGION | B3: Sum of Sum of Quantity | C3: Sum of Sum of Discount
A4: East | B4: 1447 | C4: 87.93
A5: North | B5: 1495 | C5: 89.23
A6: South | B6: 1413 | C6: 85.03
A7: West | B7: 593 | C7: 33.39
A8: Grand Total | B8: 4948 | C8: 295.58

Sheet REGION VS YEAR VS REV
A3: Sum of TOTAL REVENUE | B3: Column Labels
B4: 2023 | C4: 2024 | D4: 2025 | E4: Grand Total
A7: Row Labels
A8: East | B8: 81208.4 | C8: 343583.74 | D8: 308006.76 | E8: 732798.91
A9: North | B9: 86917.08 | C9: 398173.53 | D9: 272380.58 | E9: 757471.19
A10: South | B10: 74734.64 | C10: 388096.11 | D10: 281398.19 | E10: 744228.94
A11: West | B11: 20832.84 | C11: 154447.54 | D11: 141287.56 | E11: 316567.94
A12: Grand Total | B12: 263692.96 | C12: 1284300.9 | D12: 1003073.1 | E12: 2551067

Sheet CATEGORY
A1: S.NO | B1: CATEGORY | C1: TOTAL COST | D1: TOTAL STOCK
A2: 1 | B2: Beauty | C2: =SUM(Product_Dim!H6:H96) -> 22902.942 | D2: =SUM(Product_Dim!I6:I96) -> 25250.866
A3: 2 | B3: Clothing | C3: =SUM(Product_Dim!H3:H98) -> 24412.882 | D3: =SUM(Product_Dim!I3:I98) -> 26230.462
A4: 3 | B4: Electronics | C4: =SUM(Product_Dim!H2:H100) -> 25202.952 | D4: =SUM(Product_Dim!I2:I100) -> 27190.462
A5: 4 | B5: Home | C5: =SUM(Product_Dim!H4:H101) -> 24949.382 | D5: =SUM(Product_Dim!I4:I101) -> 26739.462
A6: 5 | B6: Sports | C6: =SUM(Product_Dim!H11:H99) -> 22359.222 | D6: =SUM(Product_Dim!I11:I99) -> 24030.866
A9: CATEGORY | B9: Sum of TOTAL COST | C9: Sum of TOTAL STOCK
A10: Beauty | B10: 22902.942 | C10: 25250.866
A11: Clothing | B11: 24412.882 | C11: 26230.462
A12: Electronics | B12: 25202.952 | C12: 27190.462
A13: Home | B13: 24949.382 | C13: 26739.462
A14: Sports | B14: 22359.222 | C14: 24030.866
A15: Grand Total | B15: 119827.38 | C15: 129442.12

Sheet REGION
A1: S.NO | B1: REGION | C1: TOTAL REVENUE
A2: 1 | B2: NORTH | C2: 757471.19
A3: 2 | B3: WEST | C3: 316567.94
A4: 3 | B4: SOUTH | C4: 744228.94
A5: 4 | B5: EAST | C5: 732798.91
A7: Row Labels | B7: Sum of TOTAL REVENUE
A8: EAST | B8: 732798.91
A9: NORTH | B9: 757471.19
A10: SOUTH | B10: 744228.94
A11: WEST | B11: 316567.94
A12: Grand Total | B12: 2551067

Sheet charts
F1: REGION BASED STORE REVENUE ANALYSIS
